[2022-06-07 10:18:10,489] {taskinstance.py:1159} INFO - Dependencies all met for <TaskInstance: first_dag.first_dag manual__2022-06-07T10:18:08.997944+00:00 [queued]>
[2022-06-07 10:18:10,535] {taskinstance.py:1159} INFO - Dependencies all met for <TaskInstance: first_dag.first_dag manual__2022-06-07T10:18:08.997944+00:00 [queued]>
[2022-06-07 10:18:10,540] {taskinstance.py:1356} INFO - 
--------------------------------------------------------------------------------
[2022-06-07 10:18:10,540] {taskinstance.py:1357} INFO - Starting attempt 1 of 2
[2022-06-07 10:18:10,540] {taskinstance.py:1358} INFO - 
--------------------------------------------------------------------------------
[2022-06-07 10:18:10,621] {taskinstance.py:1377} INFO - Executing <Task(PythonOperator): first_dag> on 2022-06-07 10:18:08.997944+00:00
[2022-06-07 10:18:10,631] {standard_task_runner.py:52} INFO - Started process 155 to run task
[2022-06-07 10:18:10,650] {standard_task_runner.py:79} INFO - Running: ['***', 'tasks', 'run', 'first_dag', 'first_dag', 'manual__2022-06-07T10:18:08.997944+00:00', '--job-id', '42', '--raw', '--subdir', 'DAGS_FOLDER/first_dag.py', '--cfg-path', '/tmp/tmpu0whhouf', '--error-file', '/tmp/tmpd5aq2hhm']
[2022-06-07 10:18:10,664] {standard_task_runner.py:80} INFO - Job 42: Subtask first_dag
[2022-06-07 10:18:10,858] {task_command.py:370} INFO - Running <TaskInstance: first_dag.first_dag manual__2022-06-07T10:18:08.997944+00:00 [running]> on host 4474c3859ebb
[2022-06-07 10:18:11,229] {taskinstance.py:1571} INFO - Exporting the following env vars:
AIRFLOW_CTX_DAG_OWNER=***
AIRFLOW_CTX_DAG_ID=first_dag
AIRFLOW_CTX_TASK_ID=first_dag
AIRFLOW_CTX_EXECUTION_DATE=2022-06-07T10:18:08.997944+00:00
AIRFLOW_CTX_TRY_NUMBER=1
AIRFLOW_CTX_DAG_RUN_ID=manual__2022-06-07T10:18:08.997944+00:00
[2022-06-07 10:18:11,230] {logging_mixin.py:115} INFO - FIRST EXECUTION
[2022-06-07 10:18:11,230] {taskinstance.py:1889} ERROR - Task failed with exception
Traceback (most recent call last):
  File "/home/airflow/.local/lib/python3.7/site-packages/airflow/operators/python.py", line 171, in execute
    return_value = self.execute_callable()
  File "/home/airflow/.local/lib/python3.7/site-packages/airflow/operators/python.py", line 189, in execute_callable
    return self.python_callable(*self.op_args, **self.op_kwargs)
  File "/opt/airflow/dags/first_dag.py", line 12, in first_execution
    context["test"].xcom_push(key="mkey", value="first_function_execution")
KeyError: 'test'
[2022-06-07 10:18:11,263] {taskinstance.py:1400} INFO - Marking task as UP_FOR_RETRY. dag_id=first_dag, task_id=first_dag, execution_date=20220607T101808, start_date=20220607T101810, end_date=20220607T101811
[2022-06-07 10:18:11,299] {standard_task_runner.py:97} ERROR - Failed to execute job 42 for task first_dag ('test'; 155)
[2022-06-07 10:18:11,359] {local_task_job.py:156} INFO - Task exited with return code 1
[2022-06-07 10:18:11,461] {local_task_job.py:273} INFO - 0 downstream tasks scheduled from follow-on schedule check
