[2022-06-07 10:00:50,501] {taskinstance.py:1159} INFO - Dependencies all met for <TaskInstance: first_dag.first_dag manual__2022-06-07T10:00:49.336486+00:00 [queued]>
[2022-06-07 10:00:50,559] {taskinstance.py:1159} INFO - Dependencies all met for <TaskInstance: first_dag.first_dag manual__2022-06-07T10:00:49.336486+00:00 [queued]>
[2022-06-07 10:00:50,560] {taskinstance.py:1356} INFO - 
--------------------------------------------------------------------------------
[2022-06-07 10:00:50,560] {taskinstance.py:1357} INFO - Starting attempt 1 of 2
[2022-06-07 10:00:50,561] {taskinstance.py:1358} INFO - 
--------------------------------------------------------------------------------
[2022-06-07 10:00:50,625] {taskinstance.py:1377} INFO - Executing <Task(PythonOperator): first_dag> on 2022-06-07 10:00:49.336486+00:00
[2022-06-07 10:00:50,632] {standard_task_runner.py:52} INFO - Started process 108 to run task
[2022-06-07 10:00:50,654] {standard_task_runner.py:79} INFO - Running: ['***', 'tasks', 'run', 'first_dag', 'first_dag', 'manual__2022-06-07T10:00:49.336486+00:00', '--job-id', '27', '--raw', '--subdir', 'DAGS_FOLDER/first_dag.py', '--cfg-path', '/tmp/tmpr08k5yux', '--error-file', '/tmp/tmp3nw5o3hm']
[2022-06-07 10:00:50,654] {standard_task_runner.py:80} INFO - Job 27: Subtask first_dag
[2022-06-07 10:00:50,848] {task_command.py:370} INFO - Running <TaskInstance: first_dag.first_dag manual__2022-06-07T10:00:49.336486+00:00 [running]> on host 455352ccbfe0
[2022-06-07 10:00:51,023] {taskinstance.py:1571} INFO - Exporting the following env vars:
AIRFLOW_CTX_DAG_OWNER=***
AIRFLOW_CTX_DAG_ID=first_dag
AIRFLOW_CTX_TASK_ID=first_dag
AIRFLOW_CTX_EXECUTION_DATE=2022-06-07T10:00:49.336486+00:00
AIRFLOW_CTX_TRY_NUMBER=1
AIRFLOW_CTX_DAG_RUN_ID=manual__2022-06-07T10:00:49.336486+00:00
[2022-06-07 10:00:51,025] {taskinstance.py:1889} ERROR - Task failed with exception
Traceback (most recent call last):
  File "/home/airflow/.local/lib/python3.7/site-packages/airflow/operators/python.py", line 171, in execute
    return_value = self.execute_callable()
  File "/home/airflow/.local/lib/python3.7/site-packages/airflow/operators/python.py", line 189, in execute_callable
    return self.python_callable(*self.op_args, **self.op_kwargs)
TypeError: first_execution() takes 0 positional arguments but 1 was given
[2022-06-07 10:00:51,046] {taskinstance.py:1400} INFO - Marking task as UP_FOR_RETRY. dag_id=first_dag, task_id=first_dag, execution_date=20220607T100049, start_date=20220607T100050, end_date=20220607T100051
[2022-06-07 10:00:51,075] {standard_task_runner.py:97} ERROR - Failed to execute job 27 for task first_dag (first_execution() takes 0 positional arguments but 1 was given; 108)
[2022-06-07 10:00:51,112] {local_task_job.py:156} INFO - Task exited with return code 1
[2022-06-07 10:00:51,199] {local_task_job.py:273} INFO - 0 downstream tasks scheduled from follow-on schedule check
