[2022-06-07 10:01:51,821] {taskinstance.py:1159} INFO - Dependencies all met for <TaskInstance: first_dag.first_dag scheduled__2022-06-07T09:00:00+00:00 [queued]>
[2022-06-07 10:01:51,836] {taskinstance.py:1159} INFO - Dependencies all met for <TaskInstance: first_dag.first_dag scheduled__2022-06-07T09:00:00+00:00 [queued]>
[2022-06-07 10:01:51,836] {taskinstance.py:1356} INFO - 
--------------------------------------------------------------------------------
[2022-06-07 10:01:51,837] {taskinstance.py:1357} INFO - Starting attempt 2 of 2
[2022-06-07 10:01:51,837] {taskinstance.py:1358} INFO - 
--------------------------------------------------------------------------------
[2022-06-07 10:01:51,869] {taskinstance.py:1377} INFO - Executing <Task(PythonOperator): first_dag> on 2022-06-07 09:00:00+00:00
[2022-06-07 10:01:51,873] {standard_task_runner.py:52} INFO - Started process 156 to run task
[2022-06-07 10:01:51,877] {standard_task_runner.py:79} INFO - Running: ['***', 'tasks', 'run', 'first_dag', 'first_dag', 'scheduled__2022-06-07T09:00:00+00:00', '--job-id', '29', '--raw', '--subdir', 'DAGS_FOLDER/first_dag.py', '--cfg-path', '/tmp/tmpncqxw2qx', '--error-file', '/tmp/tmp2ny3hcec']
[2022-06-07 10:01:51,878] {standard_task_runner.py:80} INFO - Job 29: Subtask first_dag
[2022-06-07 10:01:51,992] {task_command.py:370} INFO - Running <TaskInstance: first_dag.first_dag scheduled__2022-06-07T09:00:00+00:00 [running]> on host 455352ccbfe0
[2022-06-07 10:01:52,164] {taskinstance.py:1571} INFO - Exporting the following env vars:
AIRFLOW_CTX_DAG_OWNER=***
AIRFLOW_CTX_DAG_ID=first_dag
AIRFLOW_CTX_TASK_ID=first_dag
AIRFLOW_CTX_EXECUTION_DATE=2022-06-07T09:00:00+00:00
AIRFLOW_CTX_TRY_NUMBER=2
AIRFLOW_CTX_DAG_RUN_ID=scheduled__2022-06-07T09:00:00+00:00
[2022-06-07 10:01:52,166] {taskinstance.py:1889} ERROR - Task failed with exception
Traceback (most recent call last):
  File "/home/airflow/.local/lib/python3.7/site-packages/airflow/operators/python.py", line 171, in execute
    return_value = self.execute_callable()
  File "/home/airflow/.local/lib/python3.7/site-packages/airflow/operators/python.py", line 189, in execute_callable
    return self.python_callable(*self.op_args, **self.op_kwargs)
TypeError: first_execution() takes 0 positional arguments but 1 was given
[2022-06-07 10:01:52,177] {taskinstance.py:1400} INFO - Marking task as FAILED. dag_id=first_dag, task_id=first_dag, execution_date=20220607T090000, start_date=20220607T100151, end_date=20220607T100152
[2022-06-07 10:01:52,197] {standard_task_runner.py:97} ERROR - Failed to execute job 29 for task first_dag (first_execution() takes 0 positional arguments but 1 was given; 156)
[2022-06-07 10:01:52,210] {local_task_job.py:156} INFO - Task exited with return code 1
[2022-06-07 10:01:52,317] {local_task_job.py:273} INFO - 0 downstream tasks scheduled from follow-on schedule check
[2022-06-07 10:07:41,666] {taskinstance.py:1159} INFO - Dependencies all met for <TaskInstance: first_dag.first_dag scheduled__2022-06-07T09:00:00+00:00 [queued]>
[2022-06-07 10:07:41,681] {taskinstance.py:1159} INFO - Dependencies all met for <TaskInstance: first_dag.first_dag scheduled__2022-06-07T09:00:00+00:00 [queued]>
[2022-06-07 10:07:41,682] {taskinstance.py:1356} INFO - 
--------------------------------------------------------------------------------
[2022-06-07 10:07:41,682] {taskinstance.py:1357} INFO - Starting attempt 2 of 2
[2022-06-07 10:07:41,682] {taskinstance.py:1358} INFO - 
--------------------------------------------------------------------------------
[2022-06-07 10:07:41,710] {taskinstance.py:1377} INFO - Executing <Task(PythonOperator): first_dag> on 2022-06-07 09:00:00+00:00
[2022-06-07 10:07:41,716] {standard_task_runner.py:52} INFO - Started process 142 to run task
[2022-06-07 10:07:41,720] {standard_task_runner.py:79} INFO - Running: ['***', 'tasks', 'run', 'first_dag', 'first_dag', 'scheduled__2022-06-07T09:00:00+00:00', '--job-id', '34', '--raw', '--subdir', 'DAGS_FOLDER/first_dag.py', '--cfg-path', '/tmp/tmpmnf_3vmf', '--error-file', '/tmp/tmpfj03oq16']
[2022-06-07 10:07:41,720] {standard_task_runner.py:80} INFO - Job 34: Subtask first_dag
[2022-06-07 10:07:41,796] {task_command.py:370} INFO - Running <TaskInstance: first_dag.first_dag scheduled__2022-06-07T09:00:00+00:00 [running]> on host f79e6e0f3eb5
[2022-06-07 10:07:41,959] {taskinstance.py:1571} INFO - Exporting the following env vars:
AIRFLOW_CTX_DAG_OWNER=***
AIRFLOW_CTX_DAG_ID=first_dag
AIRFLOW_CTX_TASK_ID=first_dag
AIRFLOW_CTX_EXECUTION_DATE=2022-06-07T09:00:00+00:00
AIRFLOW_CTX_TRY_NUMBER=2
AIRFLOW_CTX_DAG_RUN_ID=scheduled__2022-06-07T09:00:00+00:00
[2022-06-07 10:07:41,960] {taskinstance.py:1889} ERROR - Task failed with exception
Traceback (most recent call last):
  File "/home/airflow/.local/lib/python3.7/site-packages/airflow/operators/python.py", line 171, in execute
    return_value = self.execute_callable()
  File "/home/airflow/.local/lib/python3.7/site-packages/airflow/operators/python.py", line 189, in execute_callable
    return self.python_callable(*self.op_args, **self.op_kwargs)
TypeError: first_execution() takes 0 positional arguments but 1 was given
[2022-06-07 10:07:41,988] {taskinstance.py:1400} INFO - Marking task as FAILED. dag_id=first_dag, task_id=first_dag, execution_date=20220607T090000, start_date=20220607T100741, end_date=20220607T100741
[2022-06-07 10:07:42,027] {standard_task_runner.py:97} ERROR - Failed to execute job 34 for task first_dag (first_execution() takes 0 positional arguments but 1 was given; 142)
[2022-06-07 10:07:42,064] {local_task_job.py:156} INFO - Task exited with return code 1
[2022-06-07 10:07:42,158] {local_task_job.py:273} INFO - 0 downstream tasks scheduled from follow-on schedule check
[2022-06-07 10:14:02,149] {taskinstance.py:1159} INFO - Dependencies all met for <TaskInstance: first_dag.first_dag scheduled__2022-06-07T09:00:00+00:00 [queued]>
[2022-06-07 10:14:02,167] {taskinstance.py:1159} INFO - Dependencies all met for <TaskInstance: first_dag.first_dag scheduled__2022-06-07T09:00:00+00:00 [queued]>
[2022-06-07 10:14:02,167] {taskinstance.py:1356} INFO - 
--------------------------------------------------------------------------------
[2022-06-07 10:14:02,167] {taskinstance.py:1357} INFO - Starting attempt 2 of 2
[2022-06-07 10:14:02,168] {taskinstance.py:1358} INFO - 
--------------------------------------------------------------------------------
[2022-06-07 10:14:02,198] {taskinstance.py:1377} INFO - Executing <Task(PythonOperator): first_dag> on 2022-06-07 09:00:00+00:00
[2022-06-07 10:14:02,203] {standard_task_runner.py:52} INFO - Started process 171 to run task
[2022-06-07 10:14:02,206] {standard_task_runner.py:79} INFO - Running: ['***', 'tasks', 'run', 'first_dag', 'first_dag', 'scheduled__2022-06-07T09:00:00+00:00', '--job-id', '39', '--raw', '--subdir', 'DAGS_FOLDER/first_dag.py', '--cfg-path', '/tmp/tmpg1kkx16f', '--error-file', '/tmp/tmpvb088w4f']
[2022-06-07 10:14:02,206] {standard_task_runner.py:80} INFO - Job 39: Subtask first_dag
[2022-06-07 10:14:02,282] {task_command.py:370} INFO - Running <TaskInstance: first_dag.first_dag scheduled__2022-06-07T09:00:00+00:00 [running]> on host 4474c3859ebb
[2022-06-07 10:14:02,395] {taskinstance.py:1571} INFO - Exporting the following env vars:
AIRFLOW_CTX_DAG_OWNER=***
AIRFLOW_CTX_DAG_ID=first_dag
AIRFLOW_CTX_TASK_ID=first_dag
AIRFLOW_CTX_EXECUTION_DATE=2022-06-07T09:00:00+00:00
AIRFLOW_CTX_TRY_NUMBER=2
AIRFLOW_CTX_DAG_RUN_ID=scheduled__2022-06-07T09:00:00+00:00
[2022-06-07 10:14:02,396] {taskinstance.py:1889} ERROR - Task failed with exception
Traceback (most recent call last):
  File "/home/airflow/.local/lib/python3.7/site-packages/airflow/operators/python.py", line 171, in execute
    return_value = self.execute_callable()
  File "/home/airflow/.local/lib/python3.7/site-packages/airflow/operators/python.py", line 189, in execute_callable
    return self.python_callable(*self.op_args, **self.op_kwargs)
TypeError: first_execution() takes 0 positional arguments but 1 was given
[2022-06-07 10:14:02,410] {taskinstance.py:1400} INFO - Marking task as FAILED. dag_id=first_dag, task_id=first_dag, execution_date=20220607T090000, start_date=20220607T101402, end_date=20220607T101402
[2022-06-07 10:14:02,429] {standard_task_runner.py:97} ERROR - Failed to execute job 39 for task first_dag (first_execution() takes 0 positional arguments but 1 was given; 171)
[2022-06-07 10:14:02,458] {local_task_job.py:156} INFO - Task exited with return code 1
[2022-06-07 10:14:02,530] {local_task_job.py:273} INFO - 0 downstream tasks scheduled from follow-on schedule check
[2022-06-07 10:19:11,938] {taskinstance.py:1159} INFO - Dependencies all met for <TaskInstance: first_dag.first_dag scheduled__2022-06-07T09:00:00+00:00 [queued]>
[2022-06-07 10:19:11,958] {taskinstance.py:1159} INFO - Dependencies all met for <TaskInstance: first_dag.first_dag scheduled__2022-06-07T09:00:00+00:00 [queued]>
[2022-06-07 10:19:11,958] {taskinstance.py:1356} INFO - 
--------------------------------------------------------------------------------
[2022-06-07 10:19:11,958] {taskinstance.py:1357} INFO - Starting attempt 2 of 2
[2022-06-07 10:19:11,959] {taskinstance.py:1358} INFO - 
--------------------------------------------------------------------------------
[2022-06-07 10:19:11,989] {taskinstance.py:1377} INFO - Executing <Task(PythonOperator): first_dag> on 2022-06-07 09:00:00+00:00
[2022-06-07 10:19:11,994] {standard_task_runner.py:52} INFO - Started process 203 to run task
[2022-06-07 10:19:11,999] {standard_task_runner.py:79} INFO - Running: ['***', 'tasks', 'run', 'first_dag', 'first_dag', 'scheduled__2022-06-07T09:00:00+00:00', '--job-id', '45', '--raw', '--subdir', 'DAGS_FOLDER/first_dag.py', '--cfg-path', '/tmp/tmp8cyq9edb', '--error-file', '/tmp/tmp03srbber']
[2022-06-07 10:19:11,999] {standard_task_runner.py:80} INFO - Job 45: Subtask first_dag
[2022-06-07 10:19:12,097] {task_command.py:370} INFO - Running <TaskInstance: first_dag.first_dag scheduled__2022-06-07T09:00:00+00:00 [running]> on host 4474c3859ebb
[2022-06-07 10:19:12,255] {taskinstance.py:1571} INFO - Exporting the following env vars:
AIRFLOW_CTX_DAG_OWNER=***
AIRFLOW_CTX_DAG_ID=first_dag
AIRFLOW_CTX_TASK_ID=first_dag
AIRFLOW_CTX_EXECUTION_DATE=2022-06-07T09:00:00+00:00
AIRFLOW_CTX_TRY_NUMBER=2
AIRFLOW_CTX_DAG_RUN_ID=scheduled__2022-06-07T09:00:00+00:00
[2022-06-07 10:19:12,256] {logging_mixin.py:115} INFO - FIRST EXECUTION
[2022-06-07 10:19:12,256] {taskinstance.py:1889} ERROR - Task failed with exception
Traceback (most recent call last):
  File "/home/airflow/.local/lib/python3.7/site-packages/airflow/operators/python.py", line 171, in execute
    return_value = self.execute_callable()
  File "/home/airflow/.local/lib/python3.7/site-packages/airflow/operators/python.py", line 189, in execute_callable
    return self.python_callable(*self.op_args, **self.op_kwargs)
  File "/opt/airflow/dags/first_dag.py", line 12, in first_execution
    context["test"].xcom_push(key="mkey", value="first_function_execution")
KeyError: 'test'
[2022-06-07 10:19:12,274] {taskinstance.py:1400} INFO - Marking task as FAILED. dag_id=first_dag, task_id=first_dag, execution_date=20220607T090000, start_date=20220607T101911, end_date=20220607T101912
[2022-06-07 10:19:12,302] {standard_task_runner.py:97} ERROR - Failed to execute job 45 for task first_dag ('test'; 203)
[2022-06-07 10:19:12,343] {local_task_job.py:156} INFO - Task exited with return code 1
[2022-06-07 10:19:12,423] {local_task_job.py:273} INFO - 0 downstream tasks scheduled from follow-on schedule check
