[2022-06-07 10:00:01,287] {taskinstance.py:1159} INFO - Dependencies all met for <TaskInstance: first_dag.first_dag scheduled__2022-06-07T09:00:00+00:00 [queued]>
[2022-06-07 10:00:01,306] {taskinstance.py:1159} INFO - Dependencies all met for <TaskInstance: first_dag.first_dag scheduled__2022-06-07T09:00:00+00:00 [queued]>
[2022-06-07 10:00:01,307] {taskinstance.py:1356} INFO - 
--------------------------------------------------------------------------------
[2022-06-07 10:00:01,307] {taskinstance.py:1357} INFO - Starting attempt 1 of 2
[2022-06-07 10:00:01,307] {taskinstance.py:1358} INFO - 
--------------------------------------------------------------------------------
[2022-06-07 10:00:01,339] {taskinstance.py:1377} INFO - Executing <Task(PythonOperator): first_dag> on 2022-06-07 09:00:00+00:00
[2022-06-07 10:00:01,343] {standard_task_runner.py:52} INFO - Started process 69 to run task
[2022-06-07 10:00:01,350] {standard_task_runner.py:79} INFO - Running: ['***', 'tasks', 'run', 'first_dag', 'first_dag', 'scheduled__2022-06-07T09:00:00+00:00', '--job-id', '26', '--raw', '--subdir', 'DAGS_FOLDER/first_dag.py', '--cfg-path', '/tmp/tmpzs1w4smn', '--error-file', '/tmp/tmpekm8d4u9']
[2022-06-07 10:00:01,350] {standard_task_runner.py:80} INFO - Job 26: Subtask first_dag
[2022-06-07 10:00:01,442] {task_command.py:370} INFO - Running <TaskInstance: first_dag.first_dag scheduled__2022-06-07T09:00:00+00:00 [running]> on host 455352ccbfe0
[2022-06-07 10:00:01,565] {taskinstance.py:1571} INFO - Exporting the following env vars:
AIRFLOW_CTX_DAG_OWNER=***
AIRFLOW_CTX_DAG_ID=first_dag
AIRFLOW_CTX_TASK_ID=first_dag
AIRFLOW_CTX_EXECUTION_DATE=2022-06-07T09:00:00+00:00
AIRFLOW_CTX_TRY_NUMBER=1
AIRFLOW_CTX_DAG_RUN_ID=scheduled__2022-06-07T09:00:00+00:00
[2022-06-07 10:00:01,567] {taskinstance.py:1889} ERROR - Task failed with exception
Traceback (most recent call last):
  File "/home/airflow/.local/lib/python3.7/site-packages/airflow/operators/python.py", line 171, in execute
    return_value = self.execute_callable()
  File "/home/airflow/.local/lib/python3.7/site-packages/airflow/operators/python.py", line 189, in execute_callable
    return self.python_callable(*self.op_args, **self.op_kwargs)
TypeError: first_execution() takes 0 positional arguments but 1 was given
[2022-06-07 10:00:01,581] {taskinstance.py:1400} INFO - Marking task as UP_FOR_RETRY. dag_id=first_dag, task_id=first_dag, execution_date=20220607T090000, start_date=20220607T100001, end_date=20220607T100001
[2022-06-07 10:00:01,603] {standard_task_runner.py:97} ERROR - Failed to execute job 26 for task first_dag (first_execution() takes 0 positional arguments but 1 was given; 69)
[2022-06-07 10:00:01,640] {local_task_job.py:156} INFO - Task exited with return code 1
[2022-06-07 10:00:01,708] {local_task_job.py:273} INFO - 0 downstream tasks scheduled from follow-on schedule check
[2022-06-07 10:00:50,606] {taskinstance.py:1159} INFO - Dependencies all met for <TaskInstance: first_dag.first_dag scheduled__2022-06-07T09:00:00+00:00 [queued]>
[2022-06-07 10:00:50,627] {taskinstance.py:1159} INFO - Dependencies all met for <TaskInstance: first_dag.first_dag scheduled__2022-06-07T09:00:00+00:00 [queued]>
[2022-06-07 10:00:50,627] {taskinstance.py:1356} INFO - 
--------------------------------------------------------------------------------
[2022-06-07 10:00:50,628] {taskinstance.py:1357} INFO - Starting attempt 1 of 2
[2022-06-07 10:00:50,628] {taskinstance.py:1358} INFO - 
--------------------------------------------------------------------------------
[2022-06-07 10:00:50,691] {taskinstance.py:1377} INFO - Executing <Task(PythonOperator): first_dag> on 2022-06-07 09:00:00+00:00
[2022-06-07 10:00:50,725] {standard_task_runner.py:52} INFO - Started process 109 to run task
[2022-06-07 10:00:50,743] {standard_task_runner.py:79} INFO - Running: ['***', 'tasks', 'run', 'first_dag', 'first_dag', 'scheduled__2022-06-07T09:00:00+00:00', '--job-id', '28', '--raw', '--subdir', 'DAGS_FOLDER/first_dag.py', '--cfg-path', '/tmp/tmpzmxipitw', '--error-file', '/tmp/tmpxszvc4p9']
[2022-06-07 10:00:50,743] {standard_task_runner.py:80} INFO - Job 28: Subtask first_dag
[2022-06-07 10:00:50,888] {task_command.py:370} INFO - Running <TaskInstance: first_dag.first_dag scheduled__2022-06-07T09:00:00+00:00 [running]> on host 455352ccbfe0
[2022-06-07 10:00:51,072] {taskinstance.py:1571} INFO - Exporting the following env vars:
AIRFLOW_CTX_DAG_OWNER=***
AIRFLOW_CTX_DAG_ID=first_dag
AIRFLOW_CTX_TASK_ID=first_dag
AIRFLOW_CTX_EXECUTION_DATE=2022-06-07T09:00:00+00:00
AIRFLOW_CTX_TRY_NUMBER=1
AIRFLOW_CTX_DAG_RUN_ID=scheduled__2022-06-07T09:00:00+00:00
[2022-06-07 10:00:51,073] {taskinstance.py:1889} ERROR - Task failed with exception
Traceback (most recent call last):
  File "/home/airflow/.local/lib/python3.7/site-packages/airflow/operators/python.py", line 171, in execute
    return_value = self.execute_callable()
  File "/home/airflow/.local/lib/python3.7/site-packages/airflow/operators/python.py", line 189, in execute_callable
    return self.python_callable(*self.op_args, **self.op_kwargs)
TypeError: first_execution() takes 0 positional arguments but 1 was given
[2022-06-07 10:00:51,088] {taskinstance.py:1400} INFO - Marking task as UP_FOR_RETRY. dag_id=first_dag, task_id=first_dag, execution_date=20220607T090000, start_date=20220607T100050, end_date=20220607T100051
[2022-06-07 10:00:51,109] {standard_task_runner.py:97} ERROR - Failed to execute job 28 for task first_dag (first_execution() takes 0 positional arguments but 1 was given; 109)
[2022-06-07 10:00:51,143] {local_task_job.py:156} INFO - Task exited with return code 1
[2022-06-07 10:00:51,229] {local_task_job.py:273} INFO - 0 downstream tasks scheduled from follow-on schedule check
[2022-06-07 10:06:40,090] {taskinstance.py:1159} INFO - Dependencies all met for <TaskInstance: first_dag.first_dag scheduled__2022-06-07T09:00:00+00:00 [queued]>
[2022-06-07 10:06:40,128] {taskinstance.py:1159} INFO - Dependencies all met for <TaskInstance: first_dag.first_dag scheduled__2022-06-07T09:00:00+00:00 [queued]>
[2022-06-07 10:06:40,129] {taskinstance.py:1356} INFO - 
--------------------------------------------------------------------------------
[2022-06-07 10:06:40,129] {taskinstance.py:1357} INFO - Starting attempt 1 of 2
[2022-06-07 10:06:40,129] {taskinstance.py:1358} INFO - 
--------------------------------------------------------------------------------
[2022-06-07 10:06:40,211] {taskinstance.py:1377} INFO - Executing <Task(PythonOperator): first_dag> on 2022-06-07 09:00:00+00:00
[2022-06-07 10:06:40,225] {standard_task_runner.py:52} INFO - Started process 101 to run task
[2022-06-07 10:06:40,270] {standard_task_runner.py:79} INFO - Running: ['***', 'tasks', 'run', 'first_dag', 'first_dag', 'scheduled__2022-06-07T09:00:00+00:00', '--job-id', '32', '--raw', '--subdir', 'DAGS_FOLDER/first_dag.py', '--cfg-path', '/tmp/tmpxm5kmm89', '--error-file', '/tmp/tmpsu55am3b']
[2022-06-07 10:06:40,276] {standard_task_runner.py:80} INFO - Job 32: Subtask first_dag
[2022-06-07 10:06:40,724] {task_command.py:370} INFO - Running <TaskInstance: first_dag.first_dag scheduled__2022-06-07T09:00:00+00:00 [running]> on host f79e6e0f3eb5
[2022-06-07 10:06:41,121] {taskinstance.py:1571} INFO - Exporting the following env vars:
AIRFLOW_CTX_DAG_OWNER=***
AIRFLOW_CTX_DAG_ID=first_dag
AIRFLOW_CTX_TASK_ID=first_dag
AIRFLOW_CTX_EXECUTION_DATE=2022-06-07T09:00:00+00:00
AIRFLOW_CTX_TRY_NUMBER=1
AIRFLOW_CTX_DAG_RUN_ID=scheduled__2022-06-07T09:00:00+00:00
[2022-06-07 10:06:41,123] {taskinstance.py:1889} ERROR - Task failed with exception
Traceback (most recent call last):
  File "/home/airflow/.local/lib/python3.7/site-packages/airflow/operators/python.py", line 171, in execute
    return_value = self.execute_callable()
  File "/home/airflow/.local/lib/python3.7/site-packages/airflow/operators/python.py", line 189, in execute_callable
    return self.python_callable(*self.op_args, **self.op_kwargs)
TypeError: first_execution() takes 0 positional arguments but 1 was given
[2022-06-07 10:06:41,153] {taskinstance.py:1400} INFO - Marking task as UP_FOR_RETRY. dag_id=first_dag, task_id=first_dag, execution_date=20220607T090000, start_date=20220607T100640, end_date=20220607T100641
[2022-06-07 10:06:41,190] {standard_task_runner.py:97} ERROR - Failed to execute job 32 for task first_dag (first_execution() takes 0 positional arguments but 1 was given; 101)
[2022-06-07 10:06:41,249] {local_task_job.py:156} INFO - Task exited with return code 1
[2022-06-07 10:06:41,371] {local_task_job.py:273} INFO - 0 downstream tasks scheduled from follow-on schedule check
[2022-06-07 10:13:01,042] {taskinstance.py:1159} INFO - Dependencies all met for <TaskInstance: first_dag.first_dag scheduled__2022-06-07T09:00:00+00:00 [queued]>
[2022-06-07 10:13:01,103] {taskinstance.py:1159} INFO - Dependencies all met for <TaskInstance: first_dag.first_dag scheduled__2022-06-07T09:00:00+00:00 [queued]>
[2022-06-07 10:13:01,103] {taskinstance.py:1356} INFO - 
--------------------------------------------------------------------------------
[2022-06-07 10:13:01,104] {taskinstance.py:1357} INFO - Starting attempt 1 of 2
[2022-06-07 10:13:01,104] {taskinstance.py:1358} INFO - 
--------------------------------------------------------------------------------
[2022-06-07 10:13:01,163] {taskinstance.py:1377} INFO - Executing <Task(PythonOperator): first_dag> on 2022-06-07 09:00:00+00:00
[2022-06-07 10:13:01,172] {standard_task_runner.py:52} INFO - Started process 125 to run task
[2022-06-07 10:13:01,177] {standard_task_runner.py:79} INFO - Running: ['***', 'tasks', 'run', 'first_dag', 'first_dag', 'scheduled__2022-06-07T09:00:00+00:00', '--job-id', '38', '--raw', '--subdir', 'DAGS_FOLDER/first_dag.py', '--cfg-path', '/tmp/tmpq12tj_5u', '--error-file', '/tmp/tmp6lcox_8z']
[2022-06-07 10:13:01,177] {standard_task_runner.py:80} INFO - Job 38: Subtask first_dag
[2022-06-07 10:13:01,361] {task_command.py:370} INFO - Running <TaskInstance: first_dag.first_dag scheduled__2022-06-07T09:00:00+00:00 [running]> on host 4474c3859ebb
[2022-06-07 10:13:01,601] {taskinstance.py:1571} INFO - Exporting the following env vars:
AIRFLOW_CTX_DAG_OWNER=***
AIRFLOW_CTX_DAG_ID=first_dag
AIRFLOW_CTX_TASK_ID=first_dag
AIRFLOW_CTX_EXECUTION_DATE=2022-06-07T09:00:00+00:00
AIRFLOW_CTX_TRY_NUMBER=1
AIRFLOW_CTX_DAG_RUN_ID=scheduled__2022-06-07T09:00:00+00:00
[2022-06-07 10:13:01,605] {taskinstance.py:1889} ERROR - Task failed with exception
Traceback (most recent call last):
  File "/home/airflow/.local/lib/python3.7/site-packages/airflow/operators/python.py", line 171, in execute
    return_value = self.execute_callable()
  File "/home/airflow/.local/lib/python3.7/site-packages/airflow/operators/python.py", line 189, in execute_callable
    return self.python_callable(*self.op_args, **self.op_kwargs)
TypeError: first_execution() takes 0 positional arguments but 1 was given
[2022-06-07 10:13:01,619] {taskinstance.py:1400} INFO - Marking task as UP_FOR_RETRY. dag_id=first_dag, task_id=first_dag, execution_date=20220607T090000, start_date=20220607T101301, end_date=20220607T101301
[2022-06-07 10:13:01,668] {standard_task_runner.py:97} ERROR - Failed to execute job 38 for task first_dag (first_execution() takes 0 positional arguments but 1 was given; 125)
[2022-06-07 10:13:01,695] {local_task_job.py:156} INFO - Task exited with return code 1
[2022-06-07 10:13:01,837] {local_task_job.py:273} INFO - 0 downstream tasks scheduled from follow-on schedule check
[2022-06-07 10:18:10,520] {taskinstance.py:1159} INFO - Dependencies all met for <TaskInstance: first_dag.first_dag scheduled__2022-06-07T09:00:00+00:00 [queued]>
[2022-06-07 10:18:10,557] {taskinstance.py:1159} INFO - Dependencies all met for <TaskInstance: first_dag.first_dag scheduled__2022-06-07T09:00:00+00:00 [queued]>
[2022-06-07 10:18:10,558] {taskinstance.py:1356} INFO - 
--------------------------------------------------------------------------------
[2022-06-07 10:18:10,558] {taskinstance.py:1357} INFO - Starting attempt 1 of 2
[2022-06-07 10:18:10,558] {taskinstance.py:1358} INFO - 
--------------------------------------------------------------------------------
[2022-06-07 10:18:10,666] {taskinstance.py:1377} INFO - Executing <Task(PythonOperator): first_dag> on 2022-06-07 09:00:00+00:00
[2022-06-07 10:18:10,712] {standard_task_runner.py:52} INFO - Started process 156 to run task
[2022-06-07 10:18:10,743] {standard_task_runner.py:79} INFO - Running: ['***', 'tasks', 'run', 'first_dag', 'first_dag', 'scheduled__2022-06-07T09:00:00+00:00', '--job-id', '43', '--raw', '--subdir', 'DAGS_FOLDER/first_dag.py', '--cfg-path', '/tmp/tmpmt5fwz1n', '--error-file', '/tmp/tmpmby3rq80']
[2022-06-07 10:18:10,744] {standard_task_runner.py:80} INFO - Job 43: Subtask first_dag
[2022-06-07 10:18:10,940] {task_command.py:370} INFO - Running <TaskInstance: first_dag.first_dag scheduled__2022-06-07T09:00:00+00:00 [running]> on host 4474c3859ebb
[2022-06-07 10:18:11,277] {taskinstance.py:1571} INFO - Exporting the following env vars:
AIRFLOW_CTX_DAG_OWNER=***
AIRFLOW_CTX_DAG_ID=first_dag
AIRFLOW_CTX_TASK_ID=first_dag
AIRFLOW_CTX_EXECUTION_DATE=2022-06-07T09:00:00+00:00
AIRFLOW_CTX_TRY_NUMBER=1
AIRFLOW_CTX_DAG_RUN_ID=scheduled__2022-06-07T09:00:00+00:00
[2022-06-07 10:18:11,278] {logging_mixin.py:115} INFO - FIRST EXECUTION
[2022-06-07 10:18:11,278] {taskinstance.py:1889} ERROR - Task failed with exception
Traceback (most recent call last):
  File "/home/airflow/.local/lib/python3.7/site-packages/airflow/operators/python.py", line 171, in execute
    return_value = self.execute_callable()
  File "/home/airflow/.local/lib/python3.7/site-packages/airflow/operators/python.py", line 189, in execute_callable
    return self.python_callable(*self.op_args, **self.op_kwargs)
  File "/opt/airflow/dags/first_dag.py", line 12, in first_execution
    context["test"].xcom_push(key="mkey", value="first_function_execution")
KeyError: 'test'
[2022-06-07 10:18:11,307] {taskinstance.py:1400} INFO - Marking task as UP_FOR_RETRY. dag_id=first_dag, task_id=first_dag, execution_date=20220607T090000, start_date=20220607T101810, end_date=20220607T101811
[2022-06-07 10:18:11,330] {standard_task_runner.py:97} ERROR - Failed to execute job 43 for task first_dag ('test'; 156)
[2022-06-07 10:18:11,390] {local_task_job.py:156} INFO - Task exited with return code 1
[2022-06-07 10:18:11,496] {local_task_job.py:273} INFO - 0 downstream tasks scheduled from follow-on schedule check
[2022-06-07 10:24:40,058] {taskinstance.py:1159} INFO - Dependencies all met for <TaskInstance: first_dag.first_dag scheduled__2022-06-07T09:00:00+00:00 [queued]>
[2022-06-07 10:24:40,078] {taskinstance.py:1159} INFO - Dependencies all met for <TaskInstance: first_dag.first_dag scheduled__2022-06-07T09:00:00+00:00 [queued]>
[2022-06-07 10:24:40,078] {taskinstance.py:1356} INFO - 
--------------------------------------------------------------------------------
[2022-06-07 10:24:40,078] {taskinstance.py:1357} INFO - Starting attempt 1 of 2
[2022-06-07 10:24:40,078] {taskinstance.py:1358} INFO - 
--------------------------------------------------------------------------------
[2022-06-07 10:24:40,111] {taskinstance.py:1377} INFO - Executing <Task(PythonOperator): first_dag> on 2022-06-07 09:00:00+00:00
[2022-06-07 10:24:40,117] {standard_task_runner.py:52} INFO - Started process 200 to run task
[2022-06-07 10:24:40,126] {standard_task_runner.py:79} INFO - Running: ['***', 'tasks', 'run', 'first_dag', 'first_dag', 'scheduled__2022-06-07T09:00:00+00:00', '--job-id', '76', '--raw', '--subdir', 'DAGS_FOLDER/first_dag.py', '--cfg-path', '/tmp/tmp94hdty22', '--error-file', '/tmp/tmp1wyhps6g']
[2022-06-07 10:24:40,127] {standard_task_runner.py:80} INFO - Job 76: Subtask first_dag
[2022-06-07 10:24:40,210] {task_command.py:370} INFO - Running <TaskInstance: first_dag.first_dag scheduled__2022-06-07T09:00:00+00:00 [running]> on host 2f271877a716
[2022-06-07 10:24:40,395] {taskinstance.py:1571} INFO - Exporting the following env vars:
AIRFLOW_CTX_DAG_OWNER=***
AIRFLOW_CTX_DAG_ID=first_dag
AIRFLOW_CTX_TASK_ID=first_dag
AIRFLOW_CTX_EXECUTION_DATE=2022-06-07T09:00:00+00:00
AIRFLOW_CTX_TRY_NUMBER=1
AIRFLOW_CTX_DAG_RUN_ID=scheduled__2022-06-07T09:00:00+00:00
[2022-06-07 10:24:40,396] {logging_mixin.py:115} INFO - FIRST EXECUTION
[2022-06-07 10:24:40,434] {python.py:173} INFO - Done. Returned value was: None
[2022-06-07 10:24:40,487] {taskinstance.py:1400} INFO - Marking task as SUCCESS. dag_id=first_dag, task_id=first_dag, execution_date=20220607T090000, start_date=20220607T102440, end_date=20220607T102440
[2022-06-07 10:24:40,542] {local_task_job.py:156} INFO - Task exited with return code 0
[2022-06-07 10:24:40,646] {local_task_job.py:273} INFO - 1 downstream tasks scheduled from follow-on schedule check
