[2022-06-07 10:06:40,098] {taskinstance.py:1159} INFO - Dependencies all met for <TaskInstance: first_dag.first_dag manual__2022-06-07T10:06:38.468238+00:00 [queued]>
[2022-06-07 10:06:40,119] {taskinstance.py:1159} INFO - Dependencies all met for <TaskInstance: first_dag.first_dag manual__2022-06-07T10:06:38.468238+00:00 [queued]>
[2022-06-07 10:06:40,120] {taskinstance.py:1356} INFO - 
--------------------------------------------------------------------------------
[2022-06-07 10:06:40,120] {taskinstance.py:1357} INFO - Starting attempt 1 of 2
[2022-06-07 10:06:40,120] {taskinstance.py:1358} INFO - 
--------------------------------------------------------------------------------
[2022-06-07 10:06:40,204] {taskinstance.py:1377} INFO - Executing <Task(PythonOperator): first_dag> on 2022-06-07 10:06:38.468238+00:00
[2022-06-07 10:06:40,213] {standard_task_runner.py:52} INFO - Started process 100 to run task
[2022-06-07 10:06:40,222] {standard_task_runner.py:79} INFO - Running: ['***', 'tasks', 'run', 'first_dag', 'first_dag', 'manual__2022-06-07T10:06:38.468238+00:00', '--job-id', '33', '--raw', '--subdir', 'DAGS_FOLDER/first_dag.py', '--cfg-path', '/tmp/tmp_f050pep', '--error-file', '/tmp/tmperce8ykt']
[2022-06-07 10:06:40,239] {standard_task_runner.py:80} INFO - Job 33: Subtask first_dag
[2022-06-07 10:06:40,693] {task_command.py:370} INFO - Running <TaskInstance: first_dag.first_dag manual__2022-06-07T10:06:38.468238+00:00 [running]> on host f79e6e0f3eb5
[2022-06-07 10:06:40,985] {taskinstance.py:1571} INFO - Exporting the following env vars:
AIRFLOW_CTX_DAG_OWNER=***
AIRFLOW_CTX_DAG_ID=first_dag
AIRFLOW_CTX_TASK_ID=first_dag
AIRFLOW_CTX_EXECUTION_DATE=2022-06-07T10:06:38.468238+00:00
AIRFLOW_CTX_TRY_NUMBER=1
AIRFLOW_CTX_DAG_RUN_ID=manual__2022-06-07T10:06:38.468238+00:00
[2022-06-07 10:06:40,986] {taskinstance.py:1889} ERROR - Task failed with exception
Traceback (most recent call last):
  File "/home/airflow/.local/lib/python3.7/site-packages/airflow/operators/python.py", line 171, in execute
    return_value = self.execute_callable()
  File "/home/airflow/.local/lib/python3.7/site-packages/airflow/operators/python.py", line 189, in execute_callable
    return self.python_callable(*self.op_args, **self.op_kwargs)
TypeError: first_execution() takes 0 positional arguments but 1 was given
[2022-06-07 10:06:41,017] {taskinstance.py:1400} INFO - Marking task as UP_FOR_RETRY. dag_id=first_dag, task_id=first_dag, execution_date=20220607T100638, start_date=20220607T100640, end_date=20220607T100641
[2022-06-07 10:06:41,069] {standard_task_runner.py:97} ERROR - Failed to execute job 33 for task first_dag (first_execution() takes 0 positional arguments but 1 was given; 100)
[2022-06-07 10:06:41,130] {local_task_job.py:156} INFO - Task exited with return code 1
[2022-06-07 10:06:41,242] {local_task_job.py:273} INFO - 0 downstream tasks scheduled from follow-on schedule check
